---
layout:     post
title:      "Junit4 如何测试多个异常"
subtitle:   "How to test multiple exception in Junit4"
date:       2022-07-24 17:09:00
author:     "LabMemZero"
catalog: false
header-style: text
tags:
  - Java
  - Junit4
  - 单元测试
---

项目中使用的 Junt 4.11 测试框架，在对抛出异常进行单元测试，尤其是多个异常的时候是很不方便的。经过一番查找，找到了一个比较合适的方式，同时对异常测试的几种方式做一个总结。

假设我们有一个转换年龄的方法，参数不合法时抛出异常：

```java
public static int convertAge(int age) {
    if (age < 0) {
        throw new IllegalArgumentException("age arg error");
    }
    return age >= 18 ? 1 : 0;
}
```

现在要对给这个方法写单元测试。

## `expected` 方式

```java
@Test(expected = IllegalArgumentException.class)
public void validateAgeTest() {
    convertAge(-1);
    // 代码到这里已经不会继续执行了
    Assert.assertEquals(0, 1);
    Assert.assertEquals(1, 18);
}
```

在 `@Test`注解上使用 `expected` 参数并声明异常类型即可。

这样做的优点是很方便，缺点也很明显：

1. 到抛出异常之后的代码不会在继续执行，如果想要测试传入参数不为负数的情况就要新写一个测试方法，或者把测试非负数的参数代码移动到异常的测试之前；
2. 无法知晓异常的参数信息，只知道 `convertAge` 这个方法跑出了一个 `IllegalArgumentException` 异常，  如果该方法再抛出一个相同的异常是无法分辨的。 

## `@Rule`注解

```java
@Rule
public ExpectedException expectedEx = ExpectedException.none();
@Test
public void validateAgeTest() {
    expectedEx.expect(IllegalArgumentException.class);
    expectedEx.expectMessage("age arg error");
    convertAge(-1);
    // 代码到这里已经不会继续执行了
}
```

这样比 `expected` 方式好一些，可以知道异常的具体信息，但是也同样执行到抛出异常就无法继续执行，尤其是抛出多个异常的时候，分别写很多个不同的异常测试方法。

现在对 `convertAge` 方法做一点改变，让其抛出两个异常：

```
public static int convertAge(int age) {
    if (age < 0) {
        throw new IllegalArgumentException("age less than 0");
    }
    if (age > 150) {
        throw new IllegalArgumentException("age more than 150");
    }
    return age >= 18 ? 1 : 0;
}
```

对于单个异常的测试这样的方式也许还能接受，但是如果一个方法抛出很多的异常，每个异常写一个测试方法就太麻烦了。看看 Juit 的的官方关于异常测试的[文档](https://github.com/junit-team/junit4/wiki/Exception-testing)提到了这么一个方法：

> The method `assertThrows` has been added to the `Assert` class in version 4.13. 

在 JUnit 4.13 版本了一个 `assertThrows` 来测试异常，这个方法方式可以测试多个异常，可惜项目中的 Junit 版本不满足。在 stackoverflow 搜寻一圈看到很多人提到了 使用 `try-catch `方式。

## `try-catch` 方式

```java
@Test
public void validateAgeTest() {
    try {
        convertAge(-1);
        Assert.fail("test fail");
    } catch (Exception e) {
        Assert.assertThat(e.getMessage(), CoreMatchers.containsString("age less than 0"));
    }
    try {
        convertAge(190);
        Assert.fail("test fail");
    } catch (Exception e) {
        Assert.assertThat(e.getMessage(), CoreMatchers.containsString("age more than 150"));
    }
    Assert.assertEquals(1, convertAge(19));
    // ...
}
```

使用 `try-catch` 能满足需求但是写起来太啰嗦和麻烦了，于是尝试手动实现一个类似 `assertThrows` 这样的工具来进行验证，而且希望更加简单，能够类似 `Assert.assertEquals `一样处理。

## 实现一个 `assertThrows` 方法

首先定一个会抛出异常的接口：

```java
@FunctionalInterface
public interface ThrowableRunnable {
    /**
     * 抛出异常的方法
     * @throws Throwable
     */
    void run() throws Throwable;
}
```

对于异常的判断我们希望传入一个异常类型，传入异常方法，以及对异常方法后的处理：

```java
/**
 * 断言方法抛出异常
 *
 * @param throwable         预期异常类型
 * @param throwableRunnable 运行方法
 * @param exceptionConsumer 异常额外验证
 * @param <T>
 */
private static <T extends Throwable> void assertThrows(
        Class<? extends Throwable> throwable,
        ThrowableRunnable throwableRunnable,
        Consumer<T> exceptionConsumer) {
    try {
        throwableRunnable.run();
    } catch (Throwable e) {
        Assert.assertTrue("throwable class not equal", e.getClass() == throwable);
        exceptionConsumer.accept((T) e);
        return;
    }
    Assert.fail("throwable throws nothing");
}
```

对于异常后的判断一下错误信息即可，所以可以对上面的方法进一步封装，直接把预期的错误信息传入：

```java
/**
 * 断言方法抛出异常并验证异常信息
 *
 * @param throwable         预期异常类型
 * @param errorMsg          异常信息
 * @param throwableRunnable 运行方法
 */
public static void assertThrows(
        Class<? extends Throwable> throwable,
        String errorMsg,
        ThrowableRunnable throwableRunnable) {
    assertThrows(throwable, throwableRunnable, e -> Assert.assertThat(e.getMessage(), CoreMatchers.containsString(errorMsg)));
}
```

大功告成，现在在一个测试方法测试多个异常风格变成了这样：

```java
@Test
public void validateAgeTest() {
    assertThrows(IllegalArgumentException.class, "age less than 0", 
                 () -> convertAge(-1));
    assertThrows(IllegalArgumentException.class, "age more than 150",
            			() -> convertAge(190));
    Assert.assertEquals(1, convertAge(19));
    // ...
}
```

终于不用写一堆 ` try-catch`了。

